<?xml version="1.0" encoding="utf-8"?>
<!-- This URDF was automatically created by SolidWorks to URDF Exporter! Originally created by Stephen Brawner (brawner@gmail.com) 
     Commit Version: 1.6.0-4-g7f85cfe  Build Version: 1.6.7995.38578
     For more information, please see http://wiki.ros.org/sw_urdf_exporter -->
<robot
  name="RON">
  <link
    name="base_link">
    <inertial>
      <origin
        xyz="-3.25154765148783E-17 -0.00947939432807307 -0.0502957336805078"
        rpy="0 0 0" />
      <mass
        value="2.84550967143739" />
      <inertia
        ixx="0.00424289058142404"
        ixy="-5.68559340029356E-08"
        ixz="-3.30336023062386E-07"
        iyy="0.00358374083667644"
        iyz="-1.10834503416664E-07"
        izz="0.00240980729030655" />
    </inertial>
    <visual>
      <origin
        xyz="0 0 0"
        rpy="0 0 0" />
      <geometry>
        <mesh
          filename="package://static/RON/meshes/base_link.STL" />
      </geometry>
      <material
        name="">
        <color
          rgba="0.898039215686275 0.917647058823529 0.929411764705882 1" />
      </material>
    </visual>
    <collision>
      <origin
        xyz="0 0 0"
        rpy="0 0 0" />
      <geometry>
        <mesh
          filename="package://static/RON/meshes/base_link.STL" />
      </geometry>
    </collision>
  </link>
  <link
    name="left_motor">
    <inertial>
      <origin
        xyz="1.249E-16 -0.022381 -1.6575E-15"
        rpy="0 0 0" />
      <mass
        value="1.2731" />
      <inertia
        ixx="0.0028507"
        ixy="4.9208E-18"
        ixz="-8.7678E-17"
        iyy="0.0052437"
        iyz="-1.7768E-17"
        izz="0.0028507" />
    </inertial>
    <visual>
      <origin
        xyz="0 0 0"
        rpy="0 0 0" />
      <geometry>
        <mesh
          filename="package://static/RON/meshes/left_motor.STL" />
      </geometry>
      <material
        name="">
        <color
          rgba="0.89804 0.91765 0.92941 1" />
      </material>
    </visual>
    <collision>
      <origin
        xyz="0 0 0"
        rpy="0 0 0" />
      <geometry>
        <mesh
          filename="package://static/RON/meshes/left_motor.STL" />
      </geometry>
    </collision>
  </link>
  <joint
    name="left_motor_joint"
    type="continuous">
    <origin
      xyz="0.0918 0 -0.105"
      rpy="0 -1.554 1.5708" />
    <parent
      link="base_link" />
    <child
      link="left_motor" />
    <axis
      xyz="0 1 0" />
    <limit
      lower="0"
      upper="0"
      effort="0"
      velocity="0" />
  </joint>
  <link
    name="right_motor">
    <inertial>
      <origin
        xyz="1.52655665885959E-16 -0.022380534740397 2.48195561325382E-15"
        rpy="0 0 0" />
      <mass
        value="1.27311863561262" />
      <inertia
        ixx="0.00285071508732584"
        ixy="4.91808161049018E-19"
        ixz="-9.987196074486E-17"
        iyy="0.00524367047203184"
        iyz="1.69220847597699E-17"
        izz="0.00285071508732583" />
    </inertial>
    <visual>
      <origin
        xyz="0 0 0"
        rpy="0 0 0" />
      <geometry>
        <mesh
          filename="package://static/RON/meshes/right_motor.STL" />
      </geometry>
      <material
        name="">
        <color
          rgba="0.898039215686275 0.917647058823529 0.929411764705882 1" />
      </material>
    </visual>
    <collision>
      <origin
        xyz="0 0 0"
        rpy="0 0 0" />
      <geometry>
        <mesh
          filename="package://static/RON/meshes/right_motor.STL" />
      </geometry>
    </collision>
  </link>
  <joint
    name="right_motor_joint"
    type="continuous">
    <origin
      xyz="-0.0918 0 -0.105"
      rpy="-3.1416 1.554 1.5708" />
    <parent
      link="base_link" />
    <child
      link="right_motor" />
    <axis
      xyz="0 1 0" />
    <limit
      lower="0"
      upper="0"
      effort="0"
      velocity="0" />
  </joint>
  <link
    name="arm_left_1">
    <inertial>
      <origin
        xyz="-0.00358400473639369 -1.11022302462516E-16 -0.0470762353128147"
        rpy="0 0 0" />
      <mass
        value="0.38358084568233" />
      <inertia
        ixx="0.000233096346638634"
        ixy="-3.60836035530332E-19"
        ixz="-3.53401370376615E-08"
        iyy="0.000155752908636126"
        iyz="-6.34033663302333E-20"
        izz="0.000191590913545276" />
    </inertial>
    <visual>
      <origin
        xyz="0 0 0"
        rpy="0 0 0" />
      <geometry>
        <mesh
          filename="package://static/RON/meshes/arm_left_1.STL" />
      </geometry>
      <material
        name="">
        <color
          rgba="0.898039215686275 0.917647058823529 0.929411764705882 1" />
      </material>
    </visual>
    <collision>
      <origin
        xyz="0 0 0"
        rpy="0 0 0" />
      <geometry>
        <mesh
          filename="package://static/RON/meshes/arm_left_1.STL" />
      </geometry>
    </collision>
  </link>
  <joint
    name="arm_left_joint_1"
    type="revolute">
    <origin
      xyz="0.040425 -0.0515 0.15"
      rpy="-1.5708 -0.021345 1.5708" />
    <parent
      link="base_link" />
    <child
      link="arm_left_1" />
    <axis
      xyz="0 0 1" />
    <limit
      lower="-3.1416"
      upper="3.1416"
      effort="0"
      velocity="0" />
  </joint>
  <link
    name="arm_left_2">
    <inertial>
      <origin
        xyz="-0.0149997196369248 0.0234113964166067 -0.00586526503174084"
        rpy="0 0 0" />
      <mass
        value="0.164890731587788" />
      <inertia
        ixx="0.000321582623179118"
        ixy="-7.87141555387858E-19"
        ixz="-3.53401370377376E-08"
        iyy="7.53415944547956E-05"
        iyz="1.66341202187931E-07"
        izz="0.000355987935690088" />
    </inertial>
    <visual>
      <origin
        xyz="0 0 0"
        rpy="0 0 0" />
      <geometry>
        <mesh
          filename="package://static/RON/meshes/arm_left_2.STL" />
      </geometry>
      <material
        name="">
        <color
          rgba="0.898039215686275 0.917647058823529 0.929411764705882 1" />
      </material>
    </visual>
    <collision>
      <origin
        xyz="0 0 0"
        rpy="0 0 0" />
      <geometry>
        <mesh
          filename="package://static/RON/meshes/arm_left_2.STL" />
      </geometry>
    </collision>
  </link>
  <joint
    name="arm_left_joint_2"
    type="revolute">
    <origin
      xyz="0 0 -0.0650000000000007"
      rpy="-1.57079632679491 -1.47492735456009 1.57079632679491" />
    <parent
      link="arm_left_1" />
    <child
      link="arm_left_2" />
    <axis
      xyz="0 0 1" />
    <limit
      lower="-3.1416"
      upper="3.1416"
      effort="0"
      velocity="0" />
  </joint>
  <link
    name="arm_right_1">
    <inertial>
      <origin
        xyz="0 0 0"
        rpy="0 0 0" />
      <mass
        value="0" />
      <inertia
        ixx="0"
        ixy="0"
        ixz="0"
        iyy="0"
        iyz="0"
        izz="0" />
    </inertial>
    <visual>
      <origin
        xyz="0 0 0"
        rpy="0 0 0" />
      <geometry>
        <mesh
          filename="package://static/RON/meshes/arm_right_1.STL" />
      </geometry>
      <material
        name="">
        <color
          rgba="1 1 1 1" />
      </material>
    </visual>
    <collision>
      <origin
        xyz="0 0 0"
        rpy="0 0 0" />
      <geometry>
        <mesh
          filename="package://static/RON/meshes/arm_right_1.STL" />
      </geometry>
    </collision>
  </link>
  <joint
    name="arm_right_joint_1"
    type="revolute">
    <origin
      xyz="-0.0404250000000002 -0.0514999999999999 0.15"
      rpy="-1.5707963267949 -0.16527975599906 1.5707963267949" />
    <parent
      link="base_link" />
    <child
      link="arm_right_1" />
    <axis
      xyz="0 0 1" />
    <limit
      lower="-3.1416"
      upper="3.1416"
      effort="0"
      velocity="0" />
  </joint>
  <link
    name="arm_right_2">
    <inertial>
      <origin
        xyz="-0.0149997196369248 0.0234113964166061 0.00592463828128127"
        rpy="0 0 0" />
      <mass
        value="0.164890731587788" />
      <inertia
        ixx="0.000321582623179119"
        ixy="6.94302318952509E-20"
        ixz="-3.53401370376605E-08"
        iyy="7.53415944547957E-05"
        iyz="-1.66341202183241E-07"
        izz="0.000355987935690089" />
    </inertial>
    <visual>
      <origin
        xyz="0 0 0"
        rpy="0 0 0" />
      <geometry>
        <mesh
          filename="package://static/RON/meshes/arm_right_2.STL" />
      </geometry>
      <material
        name="">
        <color
          rgba="0.898039215686275 0.917647058823529 0.929411764705882 1" />
      </material>
    </visual>
    <collision>
      <origin
        xyz="0 0 0"
        rpy="0 0 0" />
      <geometry>
        <mesh
          filename="package://static/RON/meshes/arm_right_2.STL" />
      </geometry>
    </collision>
  </link>
  <joint
    name="arm_right_joint_2"
    type="revolute">
    <origin
      xyz="0 0 0.0650000000000002"
      rpy="1.5707963267949 1.42814481894189 1.5707963267949" />
    <parent
      link="arm_right_1" />
    <child
      link="arm_right_2" />
    <axis
      xyz="0 0 1" />
    <limit
      lower="-3.1416"
      upper="3.1416"
      effort="0"
      velocity="0" />
  </joint>
</robot>