<?xml version="1.0" encoding="utf-8"?>
<!-- This URDF was automatically created by SolidWorks to URDF Exporter! Originally created by Stephen Brawner (brawner@gmail.com) 
     Commit Version: 1.6.0-4-g7f85cfe  Build Version: 1.6.7995.38578
     For more information, please see http://wiki.ros.org/sw_urdf_exporter -->
<robot
  name="RON">
  <link
    name="base_link">
    <inertial>
      <origin
        xyz="-3.1396E-17 -0.0094794 -0.050296"
        rpy="0 0 0" />
      <mass
        value="2.8455" />
      <inertia
        ixx="0.0042429"
        ixy="-5.6856E-08"
        ixz="-3.3034E-07"
        iyy="0.0035837"
        iyz="-1.1083E-07"
        izz="0.0024098" />
    </inertial>
    <visual>
      <origin
        xyz="0 0 0"
        rpy="0 0 0" />
      <geometry>
        <mesh
          filename="./meshes/base_link.obj" />
      </geometry>
      <material
        name="">
        <color
          rgba="0.89804 0.91765 0.92941 1" />
      </material>
    </visual>
    <collision>
      <origin
        xyz="0 0 0"
        rpy="0 0 0" />
      <geometry>
        <mesh
          filename="./meshes/base_link.obj" />
      </geometry>
    </collision>
  </link>
  <link
    name="left_motor">
    <inertial>
      <origin
        xyz="-4.2401E-09 -0.022611 -1.238E-08"
        rpy="0 0 0" />
      <mass
        value="1.1606" />
      <inertia
        ixx="0.0024571"
        ixy="-5.0792E-11"
        ixz="-4.1332E-10"
        iyy="0.0045348"
        iyz="-1.8299E-10"
        izz="0.0024571" />
    </inertial>
    <visual>
      <origin
        xyz="0 0 0"
        rpy="0 0 0" />
      <geometry>
        <mesh
          filename="./meshes/left_motor.obj" />
      </geometry>
      <material
        name="">
        <color
          rgba="0.89804 0.91765 0.92941 1" />
      </material>
    </visual>
    <collision>
      <origin
        xyz="0 0 0"
        rpy="0 0 0" />
      <geometry>
        <mesh
          filename="./meshes/left_motor.obj" />
      </geometry>
    </collision>
  </link>
  <joint
    name="left_motor_joint"
    type="continuous">
    <origin
      xyz="0.0918 0 -0.105"
      rpy="0 -1.554 1.5708" />
    <parent
      link="base_link" />
    <child
      link="left_motor" />
    <axis
      xyz="0 1 0" />
    <limit effort="100" />
  </joint>
  <link
    name="right_motor">
    <inertial>
      <origin
        xyz="7.03970168269841E-09 -0.0226107883538105 1.10311139270378E-08"
        rpy="0 0 0" />
      <mass
        value="1.16062119044462" />
      <inertia
        ixx="0.00245708890688505"
        ixy="9.25077801470099E-11"
        ixz="-2.25535481119372E-10"
        iyy="0.0045347876463964"
        iyz="1.65850798252249E-10"
        izz="0.00245708983584218" />
    </inertial>
    <visual>
      <origin
        xyz="0 0 0"
        rpy="0 0 0" />
      <geometry>
        <mesh
          filename="./meshes/right_motor.obj" />
      </geometry>
      <material
        name="">
        <color
          rgba="0.898039215686275 0.917647058823529 0.929411764705882 1" />
      </material>
    </visual>
    <collision>
      <origin
        xyz="0 0 0"
        rpy="0 0 0" />
      <geometry>
        <mesh
          filename="./meshes/right_motor.obj" />
      </geometry>
    </collision>
  </link>
  <joint
    name="right_motor_joint"
    type="continuous">
    <origin
      xyz="-0.0918 0 -0.105"
      rpy="-3.1416 1.554 1.5708" />
    <parent
      link="base_link" />
    <child
      link="right_motor" />
    <axis
      xyz="0 1 0" />
    <limit effort="100" />
  </joint>
  <transmission name="left_motor_effort">
    <type>hardware_interface/SimpleTransmission</type>
    <joint name="left_motor_joint">
        <hardwareInterface>EffortJointInterface</hardwareInterface>
    </joint>
    <actuator name="left_motor">
        <mechanicalReduction>1</mechanicalReduction>
        <hardwareInterface>EffortJointInterface</hardwareInterface>
    </actuator>
  </transmission>
  <transmission name="right_motor_effort">
    <type>hardware_interface/SimpleTransmission</type>
    <joint name="right_motor_joint">
        <hardwareInterface>EffortJointInterface</hardwareInterface>
    </joint>
    <actuator name="right_motor">
        <mechanicalReduction>1</mechanicalReduction>
        <hardwareInterface>EffortJointInterface</hardwareInterface>
    </actuator>
  </transmission> 
  <link
    name="arm_left_1">
    <inertial>
      <origin
        xyz="-0.003584 -8.3267E-17 -0.047076"
        rpy="0 0 0" />
      <mass
        value="0.38358" />
      <inertia
        ixx="0.0002331"
        ixy="-3.5893E-19"
        ixz="-3.534E-08"
        iyy="0.00015575"
        iyz="-6.4138E-20"
        izz="0.00019159" />
    </inertial>
    <visual>
      <origin
        xyz="0 0 0"
        rpy="0 0 0" />
      <geometry>
        <mesh
          filename="./meshes/arm_left_1.obj" />
      </geometry>
      <material
        name="">
        <color
          rgba="0.89804 0.91765 0.92941 1" />
      </material>
    </visual>
    <collision>
      <origin
        xyz="0 0 0"
        rpy="0 0 0" />
      <geometry>
        <mesh
          filename="./meshes/arm_left_1.obj" />
      </geometry>
    </collision>
  </link>
  <joint
    name="arm_left_joint_1"
    type="revolute">
    <origin
      xyz="0.040425 -0.0515 0.15"
      rpy="-1.5708 -0.021345 1.5708" />
    <parent
      link="base_link" />
    <child
      link="arm_left_1" />
    <axis
      xyz="0 0 1" />
    <limit
      lower="-3.1416"
      upper="3.1416"
      effort="100"
      velocity="100" />
  </joint>
  <link
    name="arm_left_2">
    <inertial>
      <origin
        xyz="-0.015 0.023411 -0.0058653"
        rpy="0 0 0" />
      <mass
        value="0.16489" />
      <inertia
        ixx="0.00032158"
        ixy="-7.85E-19"
        ixz="-3.534E-08"
        iyy="7.5342E-05"
        iyz="1.6634E-07"
        izz="0.00035599" />
    </inertial>
    <visual>
      <origin
        xyz="0 0 0"
        rpy="0 0 0" />
      <geometry>
        <mesh
          filename="./meshes/arm_left_2.obj" />
      </geometry>
      <material
        name="">
        <color
          rgba="0.89804 0.91765 0.92941 1" />
      </material>
    </visual>
    <collision>
      <origin
        xyz="0 0 0"
        rpy="0 0 0" />
      <geometry>
        <mesh
          filename="./meshes/arm_left_2.obj" />
      </geometry>
    </collision>
  </link>
  <joint
    name="arm_left_joint_2"
    type="revolute">
    <origin
      xyz="0 0 -0.065"
      rpy="-1.5708 -1.4749 1.5708" />
    <parent
      link="arm_left_1" />
    <child
      link="arm_left_2" />
    <axis
      xyz="0 0 1" />
    <limit
      lower="-3.1416"
      upper="3.1416"
      effort="0"
      velocity="0" />
  </joint>
  <link
    name="arm_right_1">
    <inertial>
      <origin
        xyz="-0.003584 5.5511E-17 0.047102"
        rpy="0 0 0" />
      <mass
        value="0.38358" />
      <inertia
        ixx="0.0002331"
        ixy="1.8635E-20"
        ixz="-3.534E-08"
        iyy="0.00015575"
        iyz="-3.6272E-20"
        izz="0.00019159" />
    </inertial>
    <visual>
      <origin
        xyz="0 0 0"
        rpy="0 0 0" />
      <geometry>
        <mesh
          filename="./meshes/arm_right_1.obj" />
      </geometry>
      <material
        name="">
        <color
          rgba="0.89804 0.91765 0.92941 1" />
      </material>
    </visual>
    <collision>
      <origin
        xyz="0 0 0"
        rpy="0 0 0" />
      <geometry>
        <mesh
          filename="./meshes/arm_right_1.obj" />
      </geometry>
    </collision>
  </link>
  <joint
    name="arm_right_joint_1"
    type="revolute">
    <origin
      xyz="-0.040425 -0.0515 0.15"
      rpy="-1.5708 -0.16528 1.5708" />
    <parent
      link="base_link" />
    <child
      link="arm_right_1" />
    <axis
      xyz="0 0 1" />
    <limit
      lower="-3.1416"
      upper="3.1416"
      effort="0"
      velocity="0" />
  </joint>
  <link
    name="arm_right_2">
    <inertial>
      <origin
        xyz="-0.015 0.023411 0.0059246"
        rpy="0 0 0" />
      <mass
        value="0.16489" />
      <inertia
        ixx="0.00032158"
        ixy="7.6206E-20"
        ixz="-3.534E-08"
        iyy="7.5342E-05"
        iyz="-1.6634E-07"
        izz="0.00035599" />
    </inertial>
    <visual>
      <origin
        xyz="0 0 0"
        rpy="0 0 0" />
      <geometry>
        <mesh
          filename="./meshes/arm_right_2.obj" />
      </geometry>
      <material
        name="">
        <color
          rgba="0.89804 0.91765 0.92941 1" />
      </material>
    </visual>
    <collision>
      <origin
        xyz="0 0 0"
        rpy="0 0 0" />
      <geometry>
        <mesh
          filename="./meshes/arm_right_2.obj" />
      </geometry>
    </collision>
  </link>
  <joint
    name="arm_right_joint_2"
    type="revolute">
    <origin
      xyz="0 0 0.065"
      rpy="1.5708 1.4281 1.5708" />
    <parent
      link="arm_right_1" />
    <child
      link="arm_right_2" />
    <axis
      xyz="0 0 1" />
    <limit
      lower="-3.1416"
      upper="3.1416"
      effort="0"
      velocity="0" />
  </joint>
</robot>